<?xml version='1.0'?>
<sdf version='1.4'>
	<model name="robomaker-jetbot">
		<static>false</static>

		<link name='chassis'>

			<pose>0.0 0.0 0.050 0.0 0.0 3.14</pose>

			<collision name='collision'>
				<geometry>
					<mesh>
						<uri>model://robomaker-jetbot/meshes/waveshare-jetbot-base-link-convex-hull.stl</uri>
					</mesh>
				</geometry>
				<surface>
					<friction>
						<ode>
							<mu>0</mu>
							<mu2>0</mu2>
							<slip1>1.0</slip1>
							<slip2>1.0</slip2>
						</ode>
					</friction>
				</surface>
			</collision>

			<visual name='visual'>
				<geometry>
					<mesh>
						<uri>model://robomaker-jetbot/meshes/waveshare-jetbot-base_link.dae</uri>
					</mesh>
				</geometry>
			</visual>

		</link>

		<link name="right_wheel">
			<pose>0.02 -0.048 0.032 0.0 0.0 -1.57079632679</pose>

			<collision name="collision">
				<geometry>
					<mesh>
						<uri>model://robomaker-jetbot/meshes/waveshare-jetbot-wheel_link.dae</uri>
					</mesh>
				</geometry>
			</collision>

			<visual name="visual">
				<geometry>
					<mesh>
						<uri>model://robomaker-jetbot/meshes/waveshare-jetbot-wheel_link.dae</uri>
					</mesh>
			 	</geometry>
			</visual>
		</link>

		<joint type="revolute" name="right_wheel_hinge">
			<pose>0.0 0.0 0.0 0.0 0.0 0.0</pose>
				<child>right_wheel</child>
				<parent>chassis</parent>
				<axis>
					<xyz>0 1 0</xyz>
				</axis>
		</joint>

		<link name="left_wheel">
			<pose>0.02 0.048 0.032 0.0 0.0 1.57079632679</pose>

			<collision name="collision">
				<geometry>
					<mesh>
						<uri>model://robomaker-jetbot/meshes/waveshare-jetbot-wheel_link.dae</uri>
					</mesh>
				</geometry>
			</collision>

			<visual name="visual">
				<geometry>
					<mesh>
						<uri>model://robomaker-jetbot/meshes/waveshare-jetbot-wheel_link.dae</uri>
					</mesh>
				</geometry>
			</visual>
		</link>

		<joint type="revolute" name="left_wheel_hinge">
			<pose>0.0 0.0 0.0 0.0 0.0 0.0</pose>
				<child>left_wheel</child>
				<parent>chassis</parent>
				<axis>
					<xyz>0 1 0</xyz>
				</axis>
		</joint>

		<link name="lidar_link">
			<pose>0.0103 -0.0058 0.127 0.0 0.0 3.14</pose>
			<collision name="collision">
				<geometry>
					<mesh>
						<uri>model://robomaker-jetbot/meshes/lidar-base.dae</uri>
					</mesh>
				</geometry>
			</collision>

			<visual name="visual">
				<geometry>
					<mesh>
						<uri>model://robomaker-jetbot/meshes/lidar-base.dae</uri>
					</mesh>
				</geometry>
			</visual>
		</link>

		<joint name="lidar_joint" type="fixed">
		  <parent>chassis</parent>
		  <child>lidar_link</child>
		  <pose>0.0 0.0 0.0 0.0 0.0 0.0</pose>
		  <axis>
		    <xyz>0.0 0.0 0.0</xyz>
		  </axis>
		</joint>

		<link name="lidar_top_link">
			<pose>0.0103 -0.0058 0.157 0.0 0.0 3.14</pose>

			<collision name="collision">
				<geometry>
					<mesh>
						<uri>model://robomaker-jetbot/meshes/lidar-top.dae</uri>
					</mesh>
				</geometry>
			</collision>

			<visual name="visual">

				<geometry>
					<mesh>
						<uri>model://robomaker-jetbot/meshes/lidar-top.dae</uri>
					</mesh>
				</geometry>

				<material>
            <ambient>0.0 0.0 0.2 1</ambient>
            <diffuse>0.0 0.0 0.2 1</diffuse>
            <specular>0.0 0.0 0.2 64</specular>
            <emissive>0.0 0.0 0.1 1</emissive>
        </material>

			</visual>

			<sensor type="ray" name="ydlidar_x2">

				 <pose>0 0 0.01 0.0 0.0 0.0</pose>

				<!-- Enable visualization to see the rays in the GUI -->
				<visualize>true</visualize>

				<!-- Set the update rate of the sensor -->
				<update_rate>7</update_rate>

				<ray>
					<!-- The scan element contains the horizontal and vertical beams.-->
					<scan>
						<!-- The horizontal beams -->
						<horizontal>
							<samples>3000</samples>
							<resolution>1.0</resolution>
							<min_angle>-3.14159</min_angle>
							<max_angle>3.14159</max_angle>
						</horizontal>

					</scan>

					<!-- Range defines characteristics of an individual beam -->
					<range>
						<!-- Minimum distance of the beam -->
						<min>0.1</min>
						<!-- Maximum distance of the beam -->
						<max>8.0</max>
						<!-- Linear resolution of the beam -->
						<resolution>0.01</resolution>
					</range>
				</ray>

				<plugin name="ydlidar_x2" filename="libgazebo_ros_laser.so">
						<topicName>ydlidar_x2/scan</topicName>
						<frameName>lidar_top_link</frameName>
            <robotNamespace>my_robot</robotNamespace>
        </plugin>
				<always_on>1</always_on>

			</sensor>

		</link>

		<joint name="lidar_top_joint" type="revolute">
			<parent>lidar_link</parent>
			<child>lidar_top_link</child>
			<pose>0.0 0.0 0.0 0.0 0.0 0.0</pose>
			<axis>
				<xyz>0 0 1</xyz>
				<limit>
        	<!-- Use a very large number to indicate continuous rotation -->
          <lower>-10000000000000000</lower>
          <upper>10000000000000000</upper>
        </limit>
			</axis>
		</joint>

		<link name="camera_link">
			<pose>0.075 0.0 0.0857 0 0.25 0</pose>
				<inertial>
					<mass>0.1</mass>
				</inertial>

				<visual name="visual">
					<geometry>
						<box>
							<size>0.001 0.001 0.001</size>
						</box>
					</geometry>
				</visual>

				<sensor name="camera" type="camera">
					<camera>
						<horizontal_fov>2.79253</horizontal_fov>
						<image>
							<width>1280</width>
							<height>720</height>
						</image>

						<clip>
							<near>0.01</near>
							<far>1</far>
						</clip>
					</camera>

					<always_on>1</always_on>
					<update_rate>30</update_rate>
					<visualize>true</visualize>
				</sensor>

			</link>

	  <joint name="camera_joint" type="fixed">
			<parent>chassis</parent>
			<child>camera_link</child>
			<pose>0.0 0.0 0.0 0.0 0.0 0.0</pose>
				<axis>
				<xyz>0.0 0.0 0.0</xyz>
				</axis>
		</joint>
	</model>
</sdf>
